Workbook

Sheet Check list
B1: Configuration Checklist
A3: Section | B3: Module | C3: Sequence | D3: Sheet name | E3: Configuration Items | F3: Tcode | G3: IMG Menu | H3: Status | I3: PIC
A4: Organization Structure | B4: FI | C4: 0 | D4: =B4&"."&C4 -> FI.0 | E4: Company Code | F4: OX02 | G4: Enterprise Structure → Definition → Financial Accounting → Define, Copy, Delete, Check Company Code
B5: MM | C5: 5 | D5: =B5&"."&C5 -> MM.5 | E5: Define Plant | F5: OX10 | G5: Enterprise Structure → Definition → Logistics – General → Define, Copy, Delete, Check Plant
B6: MM | C6: 10 | D6: =B6&"."&C6 -> MM.10 | E6: Define Storage Location | F6: OX09 | G6: Enterprise Structure → Definition → Materials Management → Maintain Storage Location
B7: MM | C7: 11 | D7: =B7&"."&C7 -> MM.11 | E7: Define Storage Condition
B8: SD | C8: 15 | D8: =B8&"."&C8 -> SD.15 | E8: Define Sales Organization | F8: OVX5 | G8: Enterprise Structure → Definition → Sales and Distribution → Define, Copy, Delete, Check Sales Organization
B9: SD | C9: 20 | D9: =B9&"."&C9 -> SD.20 | E9: Define Distribution Channel | F9: OVXI | G9: Enterprise Structure → Definition → Sales and Distribution → Define, Copy, Delete, Check Distribution Channel
B10: SD | C10: 25 | D10: =B10&"."&C10 -> SD.25 | E10: Define Division | F10: OVXB | G10: Enterprise Structure → Definition → Sales and Distribution → Define, Copy, Delete, Check Division
B11: SD | C11: 26 | D11: =B11&"."&C11 -> SD.26 | E11: Define Sales Office | G11: Enterprise Structure → Definition → Sales and Distribution → Maintain Storage Office
B12: SD | C12: 27 | D12: =B12&"."&C12 -> SD.27 | E12: Define Sale Groups | G12: Enterprise Structure → Definition → Sales and Distribution → Maintain Storage Groups
B13: MM/LE | C13: 30 | D13: =B13&"."&C13 -> MM/LE.30 | E13: Assign Plant to Company Code | F13: OX18 | G13: Enterprise Structure → Assignment → Logistics – General → Assign Plant to Company Code
B14: SD | C14: 35 | D14: =B14&"."&C14 -> SD.35 | E14: Assign Sales Organization to Company Code | F14: OVX3 | G14: Enterprise Structure → Assignment → Sales and Distribution → Assign Sales Organization to Company Code
B15: SD | C15: 40 | D15: =B15&"."&C15 -> SD.40 | E15: Assign Distribution Channel to Sales Organization | F15: OVXK | G15: Enterprise Structure → Assignment → Sales and Distribution → Assign Distribution Channel to Sales Organization
B16: SD | C16: 45 | D16: =B16&"."&C16 -> SD.45 | E16: Assign Division to Sales Organization | F16: OVXA | G16: Enterprise Structure → Assignment → Sales and Distribution → Assign Division to Sales Organization
B17: SD | C17: 50 | D17: =B17&"."&C17 -> SD.50 | E17: Set up Sales Area (SO/DC/Div) | F17: OVXG | G17: Enterprise Structure → Assignment → Sales and Distribution → Set up Sales Area
B18: SD | C18: 51 | D18: =B18&"."&C18 -> SD.51 | E18: Assign Sales Office to Sales Area | G18: Enterprise Structure → Assignment → Sales and Distribution → Assign Sales Office to Sales Area
B19: SD | C19: 52 | D19: =B19&"."&C19 -> SD.52 | E19: Assign Sale Groups to Sales Office | G19: Enterprise Structure → Assignment → Sales and Distribution → Assign Sale Groups to Sales Office
B20: SD/MM | C20: 55 | D20: =B20&"."&C20 -> SD/MM.55 | E20: Assign Sales Org + DC → Plant | F20: OVX6 | G20: Enterprise Structure → Assignment → Sales and Distribution → Assign Plant to Sales Organization and Distribution Channel
B21: LE | C21: 60 | D21: =B21&"."&C21 -> LE.60 | E21: Define Shipping Point | F21: OVXD | G21: Enterprise Structure → Definition → Logistics Execution → Define, Copy, Delete, Check Shipping Point
B22: LE | C22: 65 | D22: =B22&"."&C22 -> LE.65 | E22: Assign Shipping Point → Plant | F22: OVXC | G22: Enterprise Structure → Assignment → Logistics Execution → Assign Shipping Point to Plant
B23: LE | C23: 66 | D23: =B23&"."&C23 -> LE.66 | E23: Define Loading Point
B24: LE | C24: 67 | D24: =B24&"."&C24 -> LE.67 | E24: Transsportation Planning Point
B25: SD | C25: 68 | D25: =B25&"."&C25 -> SD.68 | E25: Define Customer Account group | F25: OBD2
B26: SD | C26: 69 | D26: =B26&"."&C26 -> SD.69 | E26: Define PB Grouping | F26: BUC2
B27: SD | C27: 70 | D27: =B27&"."&C27 -> SD.70 | E27: Define Loading Group | F27: SM30
B28: CA (BP) | C28: 75 | D28: =B28&"."&C28 -> CA (BP).75 | E28: Define Number Ranges for BP | F28: BUCF | G28: Cross-Application Components → SAP Business Partner → Business Partner → Basic Settings → Number Ranges and Groupings
B29: CA (BP) | C29: 80 | D29: =B29&"."&C29 -> CA (BP).80 | E29: BP Groupings & assign number ranges | F29: SPRO | G29: Cross-Application Components → SAP Business Partner → Business Partner → Basic Settings → Number Ranges and Groupings
B30: CA (BP) | C30: 85 | D30: =B30&"."&C30 -> CA (BP).85 | E30: Activate BP Role for SD Customer: FLCU01 | F30: SPRO | G30: Cross-Application Components → SAP Business Partner → Business Partner → Basic Settings → Business Partner Roles
B31: CVI | C31: 90 | D31: =B31&"."&C31 -> CVI.90 | E31: Assign BP Grouping ↔ Customer Account Group (CVI mapping) | F31: SPRO | G31: Cross-Application Components → Master Data Synchronization → Customer/Vendor Integration → Business Partner Settings → Customer Integration
B32: CVI | C32: 91 | D32: =B32&"."&C32 -> CVI.91 | E32: Assign Account Groups - Function Assignment | F32: VOPAN
B33: SD | C33: 95 | D33: =B33&"."&C33 -> SD.95 | E33: Partner Functions procedure (SP/SH/BP/PY…) | F33: VOPA | G33: Sales and Distribution → Basic Functions → Partner Determination → Set Up Partner Determination for Customer Master
B34: SD | C34: 100 | D34: =B34&"."&C34 -> SD.100 | E34: Assign Partner Determination Procedure to Sales Doc Type | F34: SPRO | G34: Sales and Distribution → Sales → Sales Documents → Sales Document Header → Assign Partner Determination Procedure
B35: SD | C35: 101 | D35: =B35&"."&C35 -> SD.101 | E35: Define Condition Table | F35: V/03
B36: SD | C36: 102 | D36: =B36&"."&C36 -> SD.102 | E36: Define Acces Sequences | F36: V/07
B37: SD | C37: 103 | D37: =B37&"."&C37 -> SD.103 | E37: Define Output Type
B38: SD | C38: 104 | D38: =B38&"."&C38 -> SD.104 | E38: Define Condition Type | F38: V/06 | G38: PRVT,KVT7
B39: SD | C39: 105 | D39: =B39&"."&C39 -> SD.105 | E39: Set Pricing Procedure | F39: V/08
B40: SD | C40: 106 | D40: =B40&"."&C40 -> SD.106 | E40: Define Customer Pricing Procedure | F40: OVKP | G40: Sales and Distribution → Basic Functions → Pricing → Pricing Control → Define Customer Pricing Procedure
B41: SD | C41: 107 | D41: =B41&"."&C41 -> SD.107 | E41: Define Document Pricing Procedure | F41: OVKK
...

Sheet FI.0
A1: back
B2: Sheet name | C2: MM.265
B3: IMG Menu | C3: =VLOOKUP(C2,'Check list'!D:G,4,0) -> Sales and Distribution → Basic Functions → Availability Check → Requirements Class
B4: Transaction Code | C4: MMNR
B5: Purpose | C5: ='Check list'!E4 -> Company Code

Sheet MM.290
A1: back
B2: Sheet name | C2: MM.290
B3: IMG Menu | C3: =VLOOKUP(C2,'Check list'!D:G,4,0) -> Materials Management → Valuation → Account Determination → Configure Automatic Postings
B4: Transaction Code | C4: OBYC
B5: Purpose | C5: Automatic Account Determination

Sheet MM.280
A1: back
B2: Sheet name | C2: MM.280
B3: IMG Menu | C3: =VLOOKUP(C2,'Check list'!D:G,4,0) -> Enterprise Structure → Definition → Logistics General → Define Valuation Level
B4: Transaction Code | C4: OMWL
B5: Purpose | C5: Define Valuation Level

Sheet MM.440
A1: back
B2: Sheet name | C2: MM.440
B3: IMG Menu | C3: =VLOOKUP(C2,'Check list'!D:G,4,0)
B4: Transaction Code | C4: VOV5
B5: Purpose | C5: Assign Schedule Line Category

Sheet MM.275
A1: back
B2: Sheet name | C2: MM.275
B3: IMG Menu | C3: =VLOOKUP(C2,'Check list'!D:G,4,0) -> SD → Sales → Sales Documents → Item Categories
B4: Transaction Code | C4: VOV6
B5: Purpose | C5: Assign Requirements Type to Item Category

Sheet MM.270
A1: back
B2: Sheet name | C2: MM.270
B3: IMG Menu | C3: =VLOOKUP(C2,'Check list'!D:G,4,0) -> Sales and Distribution → Basic Functions → Availability Check → Requirements Type
B4: Transaction Code | C4: OVZH
B5: Purpose | C5: Define Requirements Type

Sheet MM.335
A1: back
B2: Sheet name | C2: MM.335
B3: IMG Menu | C3: =VLOOKUP(C2,'Check list'!D:G,4,0)
B4: Transaction Code | C4: MMNR
B5: Purpose | C5: Assign Requirement Type

Sheet MM.265
A1: back
B2: Sheet name | C2: MM.265
B3: IMG Menu | C3: =VLOOKUP(C2,'Check list'!D:G,4,0) -> Sales and Distribution → Basic Functions → Availability Check → Requirements Class
B4: Transaction Code | C4: OVZG
B5: Purpose | C5: Define Requirements Class

Sheet MM.260
A1: back
B2: Sheet name | C2: MM.260
B3: IMG Menu | C3: =VLOOKUP(C2,'Check list'!D:G,4,0) -> Sales and Distribution → Basic Functions → Availability Check
B4: Transaction Code | C4: OVZ9
B5: Purpose | C5: Assign Checking Rule

Sheet MM.255
A1: back
B2: Sheet name | C2: MM.255
B3: IMG Menu | C3: =VLOOKUP(C2,'Check list'!D:G,4,0) -> Enterprise Structure → Assignment → Logistics Execution
B4: Transaction Code | C4: =VLOOKUP(C2,'Check list'!D:G,3,0) -> OVXC
B5: Purpose | C5: =VLOOKUP(C2,'Check list'!D:G,2,0) -> Assign Shipping Point to Plant

Sheet MM.245
A1: back
B2: Sheet name | C2: MM.245
B3: IMG Menu | C3: =VLOOKUP(C2,'Check list'!D:G,4,0) -> Enterprise Structure → Assignment → Sales and Distribution
B4: Transaction Code | C4: OMBW
B5: Purpose | C5: Define Stock Determination Rules

Sheet MM.240
A1: back
B2: Sheet name | C2: MM.240
B3: IMG Menu | C3: =VLOOKUP(C2,'Check list'!D:G,4,0) -> Materials Management → Valuation and Account Assignment → Account Determination
B4: Transaction Code | C4: OMJJ
B5: Purpose | C5: Define Movement Types

Sheet MM.230
A1: back
B2: Sheet name | C2: MM.230
B3: IMG Menu | C3: =VLOOKUP(C2,'Check list'!D:G,4,0) -> Materials Management → Inventory Management → Movement Types
B4: Transaction Code | C4: CUNI
B5: Purpose | C5: Define Units of Measure

Sheet MM.225
A1: back
B2: Sheet name | C2: MM.225
B3: IMG Menu | C3: =VLOOKUP(C2,'Check list'!D:G,4,0) -> Logistics General → Material Master → Basic Settings → Number Ranges
B4: Transaction Code | C4: MMNR
B5: Purpose | C5: Define Number Ranges for Material

Sheet MM.220
A1: back
B2: Sheet name | C2: MM.220
B3: IMG Menu | C3: =VLOOKUP(C2,'Check list'!D:G,4,0) -> Logistics General → Material Master → Basic Settings → Number Ranges
B4: Transaction Code | C4: OMS2
B5: Purpose | C5: Define Material Types

Sheet 235
A1: back
B2: Sheet name | C2: =MID(CELL("filename",A1),FIND("]",CELL("filename",A1))+1,255) -> #VALUE!
B3: IMG Menu | C3: =VLOOKUP(C2,'Check list'!D:G,4,0) -> #VALUE!
B4: Transaction Code | C4: =VLOOKUP(C2,'Check list'!D:F,3,0) -> #VALUE!
B5: Purpose | C5: ='Check list'!E4 -> Company Code

Sheet 230
A1: back
B2: Sheet name | C2: =MID(CELL("filename",A1),FIND("]",CELL("filename",A1))+1,255) -> #VALUE!
B3: IMG Menu | C3: =VLOOKUP(C2,'Check list'!D:G,4,0) -> #VALUE!
B4: Transaction Code | C4: =VLOOKUP(C2,'Check list'!D:F,3,0) -> #VALUE!
B5: Purpose | C5: ='Check list'!E105 -> Define Movement Types

Sheet 215
A1: back
B2: Sheet name | C2: =MID(CELL("filename",A1),FIND("]",CELL("filename",A1))+1,255) -> #VALUE!
B3: IMG Menu | C3: =VLOOKUP(C2,'Check list'!D:G,4,0) -> #VALUE!
B4: Transaction Code | C4: =VLOOKUP(C2,'Check list'!D:F,3,0) -> #VALUE!
B5: Purpose | C5: ='Check list'!E103 -> Define Material Types

Sheet 220
A1: back
B2: Sheet name | C2: =MID(CELL("filename",A1),FIND("]",CELL("filename",A1))+1,255) -> #VALUE!
B3: IMG Menu | C3: =VLOOKUP(C2,'Check list'!D:G,4,0) -> #VALUE!
B4: Transaction Code | C4: =VLOOKUP(C2,'Check list'!D:F,3,0) -> #VALUE!
B5: Purpose | C5: ='Check list'!E104 -> Define Number Ranges for Materials

Sheet MM.5
A1: back
B2: Sheet name | C2: =MID(CELL("filename",A1),FIND("]",CELL("filename",A1))+1,255) -> #VALUE!
B3: IMG Menu | C3: =VLOOKUP(C2,'Check list'!D:G,4,0) -> #VALUE!
B4: Transaction Code | C4: =VLOOKUP(C2,'Check list'!D:F,3,0) -> #VALUE!
B5: Purpose | C5: ='Check list'!E5 -> Define Plant

Sheet MM.10
A1: back
B2: Sheet name | C2: =MID(CELL("filename",A1),FIND("]",CELL("filename",A1))+1,255) -> #VALUE!
B3: IMG Menu | C3: =VLOOKUP(C2,'Check list'!D:G,4,0) -> #VALUE!
B4: Transaction Code | C4: =VLOOKUP(C2,'Check list'!D:F,3,0) -> #VALUE!
B5: Purpose | C5: ='Check list'!E6 -> Define Storage Location

Sheet SD.15
A1: back
B2: Sheet name | C2: =MID(CELL("filename",A1),FIND("]",CELL("filename",A1))+1,255) -> #VALUE!
B3: IMG Menu | C3: =VLOOKUP(C2,'Check list'!D:G,4,0) -> #VALUE!
B4: Transaction Code | C4: =VLOOKUP(C2,'Check list'!D:F,3,0) -> #VALUE!
B5: Purpose | C5: ='Check list'!E8 -> Define Sales Organization

Sheet SD.20
A1: back
B2: Sheet name | C2: =MID(CELL("filename",A1),FIND("]",CELL("filename",A1))+1,255) -> #VALUE!
B3: IMG Menu | C3: =VLOOKUP(C2,'Check list'!D:G,4,0) -> #VALUE!
B4: Transaction Code | C4: =VLOOKUP(C2,'Check list'!D:F,3,0) -> #VALUE!
B5: Purpose | C5: ='Check list'!E9 -> Define Distribution Channel

Sheet SD.25
A1: back
B2: Sheet name | C2: =MID(CELL("filename",A1),FIND("]",CELL("filename",A1))+1,255) -> #VALUE!
B3: IMG Menu | C3: =VLOOKUP(C2,'Check list'!D:G,4,0) -> #VALUE!
B4: Transaction Code | C4: =VLOOKUP(C2,'Check list'!D:F,3,0) -> #VALUE!
B5: Purpose | C5: ='Check list'!E10 -> Define Division

Sheet SD.26
A1: back
B2: Sheet name | C2: =MID(CELL("filename",A1),FIND("]",CELL("filename",A1))+1,255) -> #VALUE!
B3: IMG Menu | C3: =VLOOKUP(C2,'Check list'!D:G,4,0) -> #VALUE!
B4: Transaction Code | C4: =VLOOKUP(C2,'Check list'!D:F,3,0) -> #VALUE!
B5: Purpose | C5: ='Check list'!E11 -> Define Sales Office

Sheet SD.27
A1: back
B2: Sheet name | C2: =MID(CELL("filename",A1),FIND("]",CELL("filename",A1))+1,255) -> #VALUE!
B3: IMG Menu | C3: =VLOOKUP(C2,'Check list'!D:G,4,0) -> #VALUE!
B4: Transaction Code | C4: =VLOOKUP(C2,'Check list'!D:F,3,0) -> #VALUE!
B5: Purpose | C5: ='Check list'!E12 -> Define Sale Groups

Sheet MMLE.30
A1: back
B2: Sheet name | C2: MM/LE.30
B3: IMG Menu | C3: =VLOOKUP(C2,'Check list'!D:G,4,0) -> Enterprise Structure → Assignment → Logistics – General → Assign Plant to Company Code
B4: Transaction Code | C4: =VLOOKUP(C2,'Check list'!D:F,3,0) -> OX18
B5: Purpose | C5: ='Check list'!E13 -> Assign Plant to Company Code

Sheet SD.35
A1: back
B2: Sheet name | C2: =MID(CELL("filename",A1),FIND("]",CELL("filename",A1))+1,255) -> #VALUE!
B3: IMG Menu | C3: =VLOOKUP(C2,'Check list'!D:G,4,0) -> #VALUE!
B4: Transaction Code | C4: =VLOOKUP(C2,'Check list'!D:F,3,0) -> #VALUE!
B5: Purpose | C5: ='Check list'!E14 -> Assign Sales Organization to Company Code

Sheet SD.40
A1: back
B2: Sheet name | C2: =MID(CELL("filename",A1),FIND("]",CELL("filename",A1))+1,255) -> #VALUE!
B3: IMG Menu | C3: =VLOOKUP(C2,'Check list'!D:G,4,0) -> #VALUE!
B4: Transaction Code | C4: =VLOOKUP(C2,'Check list'!D:F,3,0) -> #VALUE!
B5: Purpose | C5: ='Check list'!E15 -> Assign Distribution Channel to Sales Organization

Sheet SD.45
A1: back
B2: Sheet name | C2: =MID(CELL("filename",A1),FIND("]",CELL("filename",A1))+1,255) -> #VALUE!
B3: IMG Menu | C3: =VLOOKUP(C2,'Check list'!D:G,4,0) -> #VALUE!
B4: Transaction Code | C4: =VLOOKUP(C2,'Check list'!D:F,3,0) -> #VALUE!
B5: Purpose | C5: ='Check list'!E15 -> Assign Distribution Channel to Sales Organization

Sheet SD.50
A1: back
B2: Sheet name | C2: =MID(CELL("filename",A1),FIND("]",CELL("filename",A1))+1,255) -> #VALUE!
B3: IMG Menu | C3: =VLOOKUP(C2,'Check list'!D:G,4,0) -> #VALUE!
B4: Transaction Code | C4: =VLOOKUP(C2,'Check list'!D:F,3,0) -> #VALUE!
B5: Purpose | C5: ='Check list'!E17 -> Set up Sales Area (SO/DC/Div)

Sheet SD.51
A1: back
B2: Sheet name | C2: =MID(CELL("filename",A1),FIND("]",CELL("filename",A1))+1,255) -> #VALUE!
B3: IMG Menu | C3: =VLOOKUP(C2,'Check list'!D:G,4,0) -> #VALUE!
B4: Transaction Code | C4: =VLOOKUP(C2,'Check list'!D:F,3,0) -> #VALUE!
B5: Purpose | C5: Assign Sales Office to Sales Area

Sheet SD.52
A1: back
B2: Sheet name | C2: =MID(CELL("filename",A1),FIND("]",CELL("filename",A1))+1,255) -> #VALUE!
B3: IMG Menu | C3: =VLOOKUP(C2,'Check list'!D:G,4,0) -> #VALUE!
B4: Transaction Code | C4: =VLOOKUP(C2,'Check list'!D:F,3,0) -> #VALUE!
B5: Purpose | C5: Assign Sale Groups to Sales Office

Sheet SDMM.55
A1: back
B2: Sheet name | C2: =MID(CELL("filename",A1),FIND("]",CELL("filename",A1))+1,255) -> #VALUE!
B3: IMG Menu | C3: =VLOOKUP(C2,'Check list'!D:G,4,0) -> #VALUE!
B4: Transaction Code | C4: =VLOOKUP(C2,'Check list'!D:F,3,0) -> #VALUE!
B5: Purpose | C5: ='Check list'!E20 -> Assign Sales Org + DC → Plant

Sheet LE.60
A1: back
B2: Sheet name | C2: =MID(CELL("filename",A1),FIND("]",CELL("filename",A1))+1,255) -> #VALUE!
B3: IMG Menu | C3: =VLOOKUP(C2,'Check list'!D:G,4,0) -> #VALUE!
B4: Transaction Code | C4: =VLOOKUP(C2,'Check list'!D:F,3,0) -> #VALUE!
B5: Purpose | C5: ='Check list'!E21 -> Define Shipping Point

Sheet LE.65
A1: back
B2: Sheet name | C2: =MID(CELL("filename",A1),FIND("]",CELL("filename",A1))+1,255) -> #VALUE!
B3: IMG Menu | C3: =VLOOKUP(C2,'Check list'!D:G,4,0) -> #VALUE!
B4: Transaction Code | C4: =VLOOKUP(C2,'Check list'!D:F,3,0) -> #VALUE!
B5: Purpose | C5: ='Check list'!E15 -> Assign Distribution Channel to Sales Organization

Sheet LE.66
A1: back
B2: Sheet name | C2: =MID(CELL("filename",A1),FIND("]",CELL("filename",A1))+1,255) -> #VALUE!
B3: IMG Menu | C3: =VLOOKUP(C2,'Check list'!D:G,4,0) -> #VALUE!
B4: Transaction Code | C4: =VLOOKUP(C2,'Check list'!D:F,3,0) -> #VALUE!
B5: Purpose | C5: ='Check list'!E23 -> Define Loading Point

Sheet LE.67
A1: back
B2: Sheet name | C2: =MID(CELL("filename",A1),FIND("]",CELL("filename",A1))+1,255) -> #VALUE!
B3: IMG Menu | C3: =VLOOKUP(C2,'Check list'!D:G,4,0) -> #VALUE!
B4: Transaction Code | C4: =VLOOKUP(C2,'Check list'!D:F,3,0) -> #VALUE!
B5: Purpose | C5: ='Check list'!E24 -> Transsportation Planning Point

Sheet SD.68
A1: back
B2: Sheet name | C2: SD.68
B3: IMG Menu | C3: =VLOOKUP(C2,'Check list'!D:G,4,0)
B4: Transaction Code | C4: =VLOOKUP(C2,'Check list'!D:F,3,0) -> OBD2
B5: Purpose | C5: =VLOOKUP(C2,'Check list'!D:F,2,0) -> Define Customer Account group

Sheet SD.69
A1: back
B2: Sheet name | C2: SD.69
B3: IMG Menu | C3: =VLOOKUP(C2,'Check list'!D:G,4,0)
B4: Transaction Code | C4: =VLOOKUP(C2,'Check list'!D:F,3,0) -> BUC2
B5: Purpose | C5: =VLOOKUP(C2,'Check list'!D:F,2,0) -> Define PB Grouping

Sheet SD.70
A1: back
B2: Sheet name | C2: SD.69
B3: IMG Menu | C3: =VLOOKUP(C2,'Check list'!D:G,4,0)
B4: Transaction Code | C4: =VLOOKUP(C2,'Check list'!D:F,3,0) -> BUC2
B5: Purpose | C5: =VLOOKUP(C2,'Check list'!D:F,2,0) -> Define PB Grouping

Sheet LESD.70
A1: back
B2: Sheet name | C2: =MID(CELL("filename",A1),FIND("]",CELL("filename",A1))+1,255) -> #VALUE!
B3: IMG Menu | C3: =VLOOKUP(C2,'Check list'!D:G,4,0) -> #VALUE!
B4: Transaction Code | C4: =VLOOKUP(C2,'Check list'!D:F,3,0) -> #VALUE!
B5: Purpose | C5: ='Check list'!E15 -> Assign Distribution Channel to Sales Organization

Sheet CA (BP).75
A1: back
B2: Sheet name | C2: =MID(CELL("filename",A1),FIND("]",CELL("filename",A1))+1,255) -> #VALUE!
B3: IMG Menu | C3: =VLOOKUP(C2,'Check list'!D:G,4,0) -> #VALUE!
B4: Transaction Code | C4: =VLOOKUP(C2,'Check list'!D:F,3,0) -> #VALUE!
B5: Purpose | C5: ='Check list'!E28 -> Define Number Ranges for BP

Sheet CA (BP).80
A1: back
B2: Sheet name | C2: =MID(CELL("filename",A1),FIND("]",CELL("filename",A1))+1,255) -> #VALUE!
B3: IMG Menu | C3: =VLOOKUP(C2,'Check list'!D:G,4,0) -> #VALUE!
B4: Transaction Code | C4: =VLOOKUP(C2,'Check list'!D:F,3,0) -> #VALUE!
B5: Purpose | C5: ='Check list'!E29 -> BP Groupings & assign number ranges

Sheet CA (BP).85
A1: back
B2: Sheet name | C2: CA (BP).85
B3: IMG Menu | C3: =VLOOKUP(C2,'Check list'!D:G,4,0) -> Cross-Application Components → SAP Business Partner → Business Partner → Basic Settings → Business Partner Roles
B4: Transaction Code | C4: =VLOOKUP(C2,'Check list'!D:F,3,0) -> SPRO
B5: Purpose | C5: ='Check list'!E30 -> Activate BP Role for SD Customer: FLCU01

Sheet CVI.90
A1: back
B2: Sheet name | C2: CVI.90
B3: IMG Menu | C3: =VLOOKUP(C2,'Check list'!D:G,4,0) -> Cross-Application Components → Master Data Synchronization → Customer/Vendor Integration → Business Partner Settings → Customer Integration
B4: Transaction Code | C4: =VLOOKUP(C2,'Check list'!D:F,3,0) -> SPRO
B5: Purpose | C5: =VLOOKUP(C2,'Check list'!D:F,2,0) -> Assign BP Grouping ↔ Customer Account Group (CVI mapping)

Sheet CVI.91
A1: back
B2: Sheet name | C2: CVI.91
B3: IMG Menu | C3: =VLOOKUP(C2,'Check list'!D:G,4,0)
B4: Transaction Code | C4: =VLOOKUP(C2,'Check list'!D:F,3,0) -> VOPAN
B5: Purpose | C5: =VLOOKUP(C2,'Check list'!D:F,2,0) -> Assign Account Groups - Function Assignment

Sheet 101
A1: back
B2: Sheet name | C2: =MID(CELL("filename",A1),FIND("]",CELL("filename",A1))+1,255) -> #VALUE!
B3: IMG Menu | C3: =VLOOKUP(C2,'Check list'!D:G,4,0) -> #VALUE!
B4: Transaction Code | C4: =VLOOKUP(C2,'Check list'!D:F,3,0) -> #VALUE!
B5: Purpose | C5: ='Check list'!E35 -> Define Condition Table

Sheet 102
A1: back
B2: Sheet name | C2: =MID(CELL("filename",A1),FIND("]",CELL("filename",A1))+1,255) -> #VALUE!
B3: IMG Menu | C3: =VLOOKUP(C2,'Check list'!D:G,4,0) -> #VALUE!
B4: Transaction Code | C4: =VLOOKUP(C2,'Check list'!D:F,3,0) -> #VALUE!
B5: Purpose | C5: ='Check list'!E36 -> Define Acces Sequences

Sheet 103
A1: back
B2: Sheet name | C2: =MID(CELL("filename",A1),FIND("]",CELL("filename",A1))+1,255) -> #VALUE!
B3: IMG Menu | C3: =VLOOKUP(C2,'Check list'!D:G,4,0) -> #VALUE!
B4: Transaction Code | C4: =VLOOKUP(C2,'Check list'!D:F,3,0) -> #VALUE!
B5: Purpose | C5: ='Check list'!E37 -> Define Output Type

Sheet 104
A1: back
B2: Sheet name | C2: =MID(CELL("filename",A1),FIND("]",CELL("filename",A1))+1,255) -> #VALUE!
B3: IMG Menu | C3: =VLOOKUP(C2,'Check list'!D:G,4,0) -> #VALUE!
B4: Transaction Code | C4: =VLOOKUP(C2,'Check list'!D:F,3,0) -> #VALUE!
B5: Purpose | C5: ='Check list'!E38 -> Define Condition Type

Sheet 105
A1: back
B2: Sheet name | C2: =MID(CELL("filename",A1),FIND("]",CELL("filename",A1))+1,255) -> #VALUE!
B3: IMG Menu | C3: =VLOOKUP(C2,'Check list'!D:G,4,0) -> #VALUE!
B4: Transaction Code | C4: =VLOOKUP(C2,'Check list'!D:F,3,0) -> #VALUE!
B5: Purpose | C5: ='Check list'!E39 -> Set Pricing Procedure

Sheet 106
A1: back
B2: Sheet name | C2: =MID(CELL("filename",A1),FIND("]",CELL("filename",A1))+1,255) -> #VALUE!
B3: IMG Menu | C3: =VLOOKUP(C2,'Check list'!D:G,4,0) -> #VALUE!
B4: Transaction Code | C4: =VLOOKUP(C2,'Check list'!D:F,3,0) -> #VALUE!
B5: Purpose | C5: ='Check list'!E41 -> Define Document Pricing Procedure

Sheet 107
A1: back
B2: Sheet name | C2: =MID(CELL("filename",A1),FIND("]",CELL("filename",A1))+1,255) -> #VALUE!
B3: IMG Menu | C3: =VLOOKUP(C2,'Check list'!D:G,4,0) -> #VALUE!
B4: Transaction Code | C4: =VLOOKUP(C2,'Check list'!D:F,3,0) -> #VALUE!
B5: Purpose | C5: ='Check list'!E41 -> Define Document Pricing Procedure

Sheet 108
A1: back
B2: Sheet name | C2: =MID(CELL("filename",A1),FIND("]",CELL("filename",A1))+1,255) -> #VALUE!
B3: IMG Menu | C3: =VLOOKUP(C2,'Check list'!D:G,4,0) -> #VALUE!
B4: Transaction Code | C4: =VLOOKUP(C2,'Check list'!D:F,3,0) -> #VALUE!
B5: Purpose | C5: ='Check list'!E42 -> Define Output Dertermination Procedure

Sheet 109
A1: back
B2: Sheet name | C2: =MID(CELL("filename",A1),FIND("]",CELL("filename",A1))+1,255) -> #VALUE!
B3: IMG Menu | C3: =VLOOKUP(C2,'Check list'!D:G,4,0) -> #VALUE!
B4: Transaction Code | C4: =VLOOKUP(C2,'Check list'!D:F,3,0) -> #VALUE!
B5: Purpose | C5: ='Check list'!E43 -> Assign Output Dertermination Procedure

Sheet 110
A1: back
B2: Sheet name | C2: =MID(CELL("filename",A1),FIND("]",CELL("filename",A1))+1,255) -> #VALUE!
B3: IMG Menu | C3: =VLOOKUP(C2,'Check list'!D:G,4,0) -> #VALUE!
B4: Transaction Code | C4: =VLOOKUP(C2,'Check list'!D:F,3,0) -> #VALUE!
B5: Purpose | C5: ='Check list'!E44 -> Set Pricing Procedure Determination

Sheet 111
A1: back
B2: Sheet name | C2: =MID(CELL("filename",A1),FIND("]",CELL("filename",A1))+1,255) -> #VALUE!
B3: IMG Menu | C3: =VLOOKUP(C2,'Check list'!D:G,4,0) -> #VALUE!
B4: Transaction Code | C4: =VLOOKUP(C2,'Check list'!D:F,3,0) -> #VALUE!
B5: Purpose | C5: ='Check list'!E45 -> Define Pricing Groups for Customers (vd: Bulk buyer)

Sheet 112
A1: back
B2: Sheet name | C2: =MID(CELL("filename",A1),FIND("]",CELL("filename",A1))+1,255) -> #VALUE!
B3: IMG Menu | C3: =VLOOKUP(C2,'Check list'!D:G,4,0) -> #VALUE!
B4: Transaction Code | C4: =VLOOKUP(C2,'Check list'!D:F,3,0) -> #VALUE!
B5: Purpose | C5: ='Check list'!E46 -> (NEW) Define Account Assignment Groups for Customers

Sheet 115
A1: back
B2: Sheet name | C2: =MID(CELL("filename",A1),FIND("]",CELL("filename",A1))+1,255) -> #VALUE!
B3: IMG Menu | C3: =VLOOKUP(C2,'Check list'!D:G,4,0) -> #VALUE!
B4: Transaction Code | C4: =VLOOKUP(C2,'Check list'!D:F,3,0) -> #VALUE!
B5: Purpose | C5: ='Check list'!E46 -> (NEW) Define Account Assignment Groups for Customers

Sheet 120
A1: back
B2: Sheet name | C2: =MID(CELL("filename",A1),FIND("]",CELL("filename",A1))+1,255) -> #VALUE!
B3: IMG Menu | C3: =VLOOKUP(C2,'Check list'!D:G,4,0) -> #VALUE!
B4: Transaction Code | C4: =VLOOKUP(C2,'Check list'!D:F,3,0) -> #VALUE!
B5: Purpose | C5: ='Check list'!E47 -> Define Sales District

Sheet 125
A1: back
B2: Sheet name | C2: =MID(CELL("filename",A1),FIND("]",CELL("filename",A1))+1,255) -> #VALUE!
B3: IMG Menu | C3: =VLOOKUP(C2,'Check list'!D:G,4,0) -> #VALUE!
B4: Transaction Code | C4: =VLOOKUP(C2,'Check list'!D:F,3,0) -> #VALUE!
B5: Purpose | C5: ='Check list'!E48 -> Define Sales District

Sheet 130
A1: back
B2: Sheet name | C2: =MID(CELL("filename",A1),FIND("]",CELL("filename",A1))+1,255) -> #VALUE!
B3: IMG Menu | C3: =VLOOKUP(C2,'Check list'!D:G,4,0) -> #VALUE!
B4: Transaction Code | C4: =VLOOKUP(C2,'Check list'!D:F,3,0) -> #VALUE!
B5: Purpose | C5: ='Check list'!E49 -> Define Shipping Conditions

Sheet 131
A1: back
B2: Sheet name | C2: =MID(CELL("filename",A1),FIND("]",CELL("filename",A1))+1,255) -> #VALUE!
B3: IMG Menu | C3: =VLOOKUP(C2,'Check list'!D:G,4,0) -> #VALUE!
B4: Transaction Code | C4: =VLOOKUP(C2,'Check list'!D:F,3,0) -> #VALUE!
B5: Purpose | C5: ='Check list'!E50 -> Shipping Point Determination

Sheet SD.135
A1: back
B2: Sheet name | C2: =MID(CELL("filename",A1),FIND("]",CELL("filename",A1))+1,255) -> #VALUE!
B3: IMG Menu | C3: =VLOOKUP(C2,'Check list'!D:G,4,0) -> #VALUE!
B4: Transaction Code | C4: =VLOOKUP(C2,'Check list'!D:F,3,0) -> #VALUE!
B5: Purpose | C5: ='Check list'!E52 -> Define Delivery Priorities

Sheet SD.140
A1: back
B2: Sheet name | C2: =MID(CELL("filename",A1),FIND("]",CELL("filename",A1))+1,255) -> #VALUE!
B3: IMG Menu | C3: =VLOOKUP(C2,'Check list'!D:G,4,0) -> #VALUE!
B4: Transaction Code | C4: =VLOOKUP(C2,'Check list'!D:F,3,0) -> #VALUE!
B5: Purpose | C5: ='Check list'!E53 -> Define Transportation Zones

Sheet 155
A1: back
B2: Sheet name | C2: =MID(CELL("filename",A1),FIND("]",CELL("filename",A1))+1,255) -> #VALUE!
B3: IMG Menu | C3: =VLOOKUP(C2,'Check list'!D:G,4,0) -> #VALUE!
B4: Transaction Code | C4: =VLOOKUP(C2,'Check list'!D:F,3,0) -> #VALUE!
B5: Purpose | C5: ='Check list'!E40 -> Define Customer Pricing Procedure

Sheet 156
A1: back
B2: Sheet name | C2: =MID(CELL("filename",A1),FIND("]",CELL("filename",A1))+1,255) -> #VALUE!
B3: IMG Menu | C3: =VLOOKUP(C2,'Check list'!D:G,4,0) -> #VALUE!
B4: Transaction Code | C4: =VLOOKUP(C2,'Check list'!D:F,3,0) -> #VALUE!
B5: Purpose | C5: ='Check list'!E40 -> Define Customer Pricing Procedure

Sheet 160
A1: back
B2: Sheet name | C2: =MID(CELL("filename",A1),FIND("]",CELL("filename",A1))+1,255) -> #VALUE!
B3: IMG Menu | C3: =VLOOKUP(C2,'Check list'!D:G,4,0) -> #VALUE!
B4: Transaction Code | C4: =VLOOKUP(C2,'Check list'!D:F,3,0) -> #VALUE!
B5: Purpose | C5: ='Check list'!E40 -> Define Customer Pricing Procedure

Sheet SD.175
A1: back
B2: Sheet name | C2: =MID(CELL("filename",A1),FIND("]",CELL("filename",A1))+1,255) -> #VALUE!
B3: IMG Menu | C3: =VLOOKUP(C2,'Check list'!D:G,4,0) -> #VALUE!
B4: Transaction Code | C4: =VLOOKUP(C2,'Check list'!D:F,3,0) -> #VALUE!
B5: Purpose | C5: ='Check list'!E59 -> Define Number Range for Sales Documents

Sheet SD.180
A1: back
B2: Sheet name | C2: =MID(CELL("filename",A1),FIND("]",CELL("filename",A1))+1,255) -> #VALUE!
B3: IMG Menu | C3: =VLOOKUP(C2,'Check list'!D:G,4,0) -> #VALUE!
B4: Transaction Code | C4: =VLOOKUP(C2,'Check list'!D:F,3,0) -> #VALUE!
B5: Purpose | C5: ='Check list'!E60 -> Sales Document Type

Sheet SD.185
A1: back
B2: Sheet name | C2: =MID(CELL("filename",A1),FIND("]",CELL("filename",A1))+1,255) -> #VALUE!
B3: IMG Menu | C3: =VLOOKUP(C2,'Check list'!D:G,4,0) -> #VALUE!
B4: Transaction Code | C4: =VLOOKUP(C2,'Check list'!D:F,3,0) -> #VALUE!
B5: Purpose | C5: ='Check list'!E61 -> Item Category

Sheet SD.190
A1: back
B2: Sheet name | C2: =MID(CELL("filename",A1),FIND("]",CELL("filename",A1))+1,255) -> #VALUE!
B3: IMG Menu | C3: =VLOOKUP(C2,'Check list'!D:G,4,0) -> #VALUE!
B4: Transaction Code | C4: =VLOOKUP(C2,'Check list'!D:F,3,0) -> #VALUE!
B5: Purpose | C5: ='Check list'!E62 -> Assign Item Category

Sheet SD.195
A1: back
B2: Sheet name | C2: =MID(CELL("filename",A1),FIND("]",CELL("filename",A1))+1,255) -> #VALUE!
B3: IMG Menu | C3: =VLOOKUP(C2,'Check list'!D:G,4,0) -> #VALUE!
B4: Transaction Code | C4: =VLOOKUP(C2,'Check list'!D:F,3,0) -> #VALUE!
B5: Purpose | C5: ='Check list'!E63 -> Schedule Line Category

Sheet SD.200
A1: back
B2: Sheet name | C2: =MID(CELL("filename",A1),FIND("]",CELL("filename",A1))+1,255) -> #VALUE!
B3: IMG Menu | C3: =VLOOKUP(C2,'Check list'!D:G,4,0) -> #VALUE!
B4: Transaction Code | C4: =VLOOKUP(C2,'Check list'!D:F,3,0) -> #VALUE!
B5: Purpose | C5: ='Check list'!E64 -> Assign Schedule Line

Sheet SD.205
A1: back
B2: Sheet name | C2: =MID(CELL("filename",A1),FIND("]",CELL("filename",A1))+1,255) -> #VALUE!
B3: IMG Menu | C3: =VLOOKUP(C2,'Check list'!D:G,4,0) -> #VALUE!
B4: Transaction Code | C4: =VLOOKUP(C2,'Check list'!D:F,3,0) -> #VALUE!
B5: Purpose | C5: ='Check list'!E65 -> Copy Control (Quotation → SO)

Sheet SD.210
A1: back
B2: Sheet name | C2: =MID(CELL("filename",A1),FIND("]",CELL("filename",A1))+1,255) -> #VALUE!
B3: IMG Menu | C3: =VLOOKUP(C2,'Check list'!D:G,4,0) -> #VALUE!
B4: Transaction Code | C4: =VLOOKUP(C2,'Check list'!D:F,3,0) -> #VALUE!
B5: Purpose | C5: ='Check list'!E66 -> Credit Management

Sheet FI.225
A1: back
B2: Sheet name | C2: =MID(CELL("filename",A1),FIND("]",CELL("filename",A1))+1,255) -> #VALUE!
B3: IMG Menu | C3: =VLOOKUP(C2,'Check list'!D:G,4,0) -> #VALUE!
B4: Transaction Code | C4: =VLOOKUP(C2,'Check list'!D:F,3,0) -> #VALUE!
B5: Purpose | C5: ='Check list'!E67 -> Define Fiscal Year Variant

Sheet FI.230
A1: back
B2: Sheet name | C2: =MID(CELL("filename",A1),FIND("]",CELL("filename",A1))+1,255) -> #VALUE!
B3: IMG Menu | C3: =VLOOKUP(C2,'Check list'!D:G,4,0) -> #VALUE!
B4: Transaction Code | C4: =VLOOKUP(C2,'Check list'!D:F,3,0) -> #VALUE!
B5: Purpose | C5: ='Check list'!E68 -> Assign Fiscal Year Variant to Company Code

Sheet FI.235
A1: back
B2: Sheet name | C2: =MID(CELL("filename",A1),FIND("]",CELL("filename",A1))+1,255) -> #VALUE!
B3: IMG Menu | C3: =VLOOKUP(C2,'Check list'!D:G,4,0) -> #VALUE!
B4: Transaction Code | C4: =VLOOKUP(C2,'Check list'!D:F,3,0) -> #VALUE!
B5: Purpose | C5: ='Check list'!E69 -> Define Posting Period Variant

Sheet FI.240
A1: back
B2: Sheet name | C2: =MID(CELL("filename",A1),FIND("]",CELL("filename",A1))+1,255) -> #VALUE!
B3: IMG Menu | C3: =VLOOKUP(C2,'Check list'!D:G,4,0) -> #VALUE!
B4: Transaction Code | C4: =VLOOKUP(C2,'Check list'!D:F,3,0) -> #VALUE!
B5: Purpose | C5: ='Check list'!E69 -> Define Posting Period Variant

Sheet FI.245
A1: back
B2: Sheet name | C2: =MID(CELL("filename",A1),FIND("]",CELL("filename",A1))+1,255) -> #VALUE!
B3: IMG Menu | C3: =VLOOKUP(C2,'Check list'!D:G,4,0) -> #VALUE!
B4: Transaction Code | C4: =VLOOKUP(C2,'Check list'!D:F,3,0) -> #VALUE!
B5: Purpose | C5: ='Check list'!E71 -> Open and Close Posting Periods

Sheet FI.250
A1: back
B2: Sheet name | C2: FI.250
B3: IMG Menu | C3: =VLOOKUP(C2,'Check list'!D:G,4,0) -> SPRO → IMG → Financial Accounting → Financial Accounting Global Settings → Document → Line Item → Controls → Define Field Status Variants
B4: Transaction Code | C4: =VLOOKUP(C2,'Check list'!D:F,3,0) -> OBC4
B5: Purpose | C5: ='Check list'!E72 -> Define Field Status Variant

Sheet FI.255
A1: back
B2: Sheet name | C2: =MID(CELL("filename",A1),FIND("]",CELL("filename",A1))+1,255) -> #VALUE!
B3: IMG Menu | C3: =VLOOKUP(C2,'Check list'!D:G,4,0) -> #VALUE!
B4: Transaction Code | C4: =VLOOKUP(C2,'Check list'!D:F,3,0) -> #VALUE!
B5: Purpose | C5: ='Check list'!E73 -> Assign Field Status Variant to Company Code

Sheet FI.260
A1: back
B2: Sheet name | C2: =MID(CELL("filename",A1),FIND("]",CELL("filename",A1))+1,255) -> #VALUE!
B3: IMG Menu | C3: =VLOOKUP(C2,'Check list'!D:G,4,0) -> #VALUE!
B4: Transaction Code | C4: =VLOOKUP(C2,'Check list'!D:F,3,0) -> #VALUE!
B5: Purpose | C5: ='Check list'!E74 -> Define Document Types

Sheet FI.265
A1: back
B2: Sheet name | C2: =MID(CELL("filename",A1),FIND("]",CELL("filename",A1))+1,255) -> #VALUE!
B3: IMG Menu | C3: =VLOOKUP(C2,'Check list'!D:G,4,0) -> #VALUE!
B4: Transaction Code | C4: =VLOOKUP(C2,'Check list'!D:F,3,0) -> #VALUE!
B5: Purpose | C5: ='Check list'!E75 -> Define Document Number Ranges

Sheet FI.270
A1: back
B2: Sheet name | C2: =MID(CELL("filename",A1),FIND("]",CELL("filename",A1))+1,255) -> #VALUE!
B3: IMG Menu | C3: =VLOOKUP(C2,'Check list'!D:G,4,0) -> #VALUE!
B4: Transaction Code | C4: =VLOOKUP(C2,'Check list'!D:F,3,0) -> #VALUE!
B5: Purpose | C5: ='Check list'!E76 -> Edit Chart of Accounts List

Sheet FI.275
A1: back
B2: Sheet name | C2: =MID(CELL("filename",A1),FIND("]",CELL("filename",A1))+1,255) -> #VALUE!
B3: IMG Menu | C3: =VLOOKUP(C2,'Check list'!D:G,4,0) -> #VALUE!
B4: Transaction Code | C4: =VLOOKUP(C2,'Check list'!D:F,3,0) -> #VALUE!
B5: Purpose | C5: ='Check list'!E77 -> Assign Company Code to Chart of Accounts

Sheet FI.280
A1: back
B2: Sheet name | C2: =MID(CELL("filename",A1),FIND("]",CELL("filename",A1))+1,255) -> #VALUE!
B3: IMG Menu | C3: =VLOOKUP(C2,'Check list'!D:G,4,0) -> #VALUE!
B4: Transaction Code | C4: =VLOOKUP(C2,'Check list'!D:F,3,0) -> #VALUE!
B5: Purpose | C5: ='Check list'!E78 -> Define Account Group

Sheet FI.285
A1: back
B2: Sheet name | C2: =MID(CELL("filename",A1),FIND("]",CELL("filename",A1))+1,255) -> #VALUE!
B3: IMG Menu | C3: =VLOOKUP(C2,'Check list'!D:G,4,0) -> #VALUE!
B4: Transaction Code | C4: =VLOOKUP(C2,'Check list'!D:F,3,0) -> #VALUE!
B5: Purpose | C5: ='Check list'!E79 -> Define Retained Earnings Account

Sheet FI.290
A1: back
B2: Sheet name | C2: =MID(CELL("filename",A1),FIND("]",CELL("filename",A1))+1,255) -> #VALUE!
B3: IMG Menu | C3: =VLOOKUP(C2,'Check list'!D:G,4,0) -> #VALUE!
B4: Transaction Code | C4: =VLOOKUP(C2,'Check list'!D:F,3,0) -> #VALUE!
B5: Purpose | C5: ='Check list'!E80 -> Define Account Groups with Screen Layout (Customers)

Sheet FI.295
A1: back
B2: Sheet name | C2: =MID(CELL("filename",A1),FIND("]",CELL("filename",A1))+1,255) -> #VALUE!
B3: IMG Menu | C3: =VLOOKUP(C2,'Check list'!D:G,4,0) -> #VALUE!
B4: Transaction Code | C4: =VLOOKUP(C2,'Check list'!D:F,3,0) -> #VALUE!
B5: Purpose | C5: ='Check list'!E81 -> Create Number Ranges for Customer Accounts

Sheet FI.300
A1: back
B2: Sheet name | C2: =MID(CELL("filename",A1),FIND("]",CELL("filename",A1))+1,255) -> #VALUE!
B3: IMG Menu | C3: =VLOOKUP(C2,'Check list'!D:G,4,0) -> #VALUE!
B4: Transaction Code | C4: =VLOOKUP(C2,'Check list'!D:F,3,0) -> #VALUE!
B5: Purpose | C5: ='Check list'!E82 -> Assign Number Ranges to Customer Account Groups

Sheet FI305
A1: back
B2: Sheet name | C2: =MID(CELL("filename",A1),FIND("]",CELL("filename",A1))+1,255) -> #VALUE!
B3: IMG Menu | C3: =VLOOKUP(C2,'Check list'!D:G,4,0) -> #VALUE!
B4: Transaction Code | C4: =VLOOKUP(C2,'Check list'!D:F,3,0) -> #VALUE!
B5: Purpose | C5: ='Check list'!E83 -> Define Tolerance Groups for Employees

Sheet FI.310
A1: back
B2: Sheet name | C2: =MID(CELL("filename",A1),FIND("]",CELL("filename",A1))+1,255) -> #VALUE!
B3: IMG Menu | C3: =VLOOKUP(C2,'Check list'!D:G,4,0) -> #VALUE!
B4: Transaction Code | C4: =VLOOKUP(C2,'Check list'!D:F,3,0) -> #VALUE!
B5: Purpose | C5: ='Check list'!E84 -> Define Calculation Procedures

Sheet FI.315
A1: back
B2: Sheet name | C2: =MID(CELL("filename",A1),FIND("]",CELL("filename",A1))+1,255) -> #VALUE!
B3: IMG Menu | C3: =VLOOKUP(C2,'Check list'!D:G,4,0) -> #VALUE!
B4: Transaction Code | C4: =VLOOKUP(C2,'Check list'!D:F,3,0) -> #VALUE!
B5: Purpose | C5: ='Check list'!E85 -> Assign Country to Calculation Procedure

Sheet FI.320
B2: Sheet name | C2: =MID(CELL("filename",A1),FIND("]",CELL("filename",A1))+1,255) -> #VALUE!
B3: IMG Menu | C3: =VLOOKUP(C2,'Check list'!D:G,4,0) -> #VALUE!
B4: Transaction Code | C4: =VLOOKUP(C2,'Check list'!D:F,3,0) -> #VALUE!
B5: Purpose | C5: ='Check list'!E86 -> Define Tax Codes for Sales and Purchases

Sheet FI.325
B2: Sheet name | C2: =MID(CELL("filename",A1),FIND("]",CELL("filename",A1))+1,255) -> #VALUE!
B3: IMG Menu | C3: =VLOOKUP(C2,'Check list'!D:G,4,0) -> #VALUE!
B4: Transaction Code | C4: =VLOOKUP(C2,'Check list'!D:F,3,0) -> #VALUE!
B5: Purpose | C5: ='Check list'!E87 -> Define House Banks

Sheet FI.355
B2: Sheet name | C2: =MID(CELL("filename",A1),FIND("]",CELL("filename",A1))+1,255) -> #VALUE!
B3: IMG Menu | C3: =VLOOKUP(C2,'Check list'!D:G,4,0) -> #VALUE!
B4: Transaction Code | C4: =VLOOKUP(C2,'Check list'!D:F,3,0) -> #VALUE!
B5: Purpose | C5: Define Reconciliation Accounts

Sheet FI.365
B2: Sheet name | C2: =MID(CELL("filename",A1),FIND("]",CELL("filename",A1))+1,255) -> #VALUE!
B3: IMG Menu | C3: =VLOOKUP(C2,'Check list'!D:G,4,0) -> #VALUE!
B4: Transaction Code | C4: =VLOOKUP(C2,'Check list'!D:F,3,0) -> #VALUE!
B5: Purpose | C5: Define Terms of Payment

Sheet FI.370
B2: Sheet name | C2: =MID(CELL("filename",A1),FIND("]",CELL("filename",A1))+1,255) -> #VALUE!
B3: IMG Menu | C3: =VLOOKUP(C2,'Check list'!D:G,4,0) -> #VALUE!
B4: Transaction Code | C4: =VLOOKUP(C2,'Check list'!D:F,3,0) -> #VALUE!
B5: Purpose | C5: Define Tolerance Groups for Customers

Sheet FI.380
B2: Sheet name | C2: =MID(CELL("filename",A1),FIND("]",CELL("filename",A1))+1,255) -> #VALUE!
B3: IMG Menu | C3: =VLOOKUP(C2,'Check list'!D:G,4,0) -> #VALUE!
B4: Transaction Code | C4: =VLOOKUP(C2,'Check list'!D:F,3,0) -> #VALUE!
B5: Purpose | C5: Define Dunning Procedure
