Workbook
Name ACTION: #REF!
Name Z_BE54E0AD_3725_4423_92D7_4F1C045BE1BC_.wvu.PrintArea: Statistics!$A:$F
Name Z_2C0D9096_8D85_462A_A9B5_0B488ADB4269_.wvu.PrintArea: Statistics!$A:$F
Name Z_6F1DCD5D_5DAC_4817_BF40_2B66F6F593E6_.wvu.Cols: #REF!
Name Z_BE54E0AD_3725_4423_92D7_4F1C045BE1BC_.wvu.Cols: #REF!
Name Z_BE54E0AD_3725_4423_92D7_4F1C045BE1BC_.wvu.Cols: #REF!
Name Z_2C0D9096_8D85_462A_A9B5_0B488ADB4269_.wvu.Cols: #REF!
Name Z_6F1DCD5D_5DAC_4817_BF40_2B66F6F593E6_.wvu.Cols: #REF!
Name Z_6F1DCD5D_5DAC_4817_BF40_2B66F6F593E6_.wvu.PrintArea: Statistics!$A:$F
Name Z_2C0D9096_8D85_462A_A9B5_0B488ADB4269_.wvu.Cols: #REF!

Sheet Main
H18: CAPSTONE PROJECT REPORT
H19: Sales and Distribution
H20: Unit Test

Sheet Guideline
A3: 1. Overview
A4: - In the template, Unit test cases are based on functions. Each sheet presents test cases for one function.
A5: - Cover: General information of the project and Unit Test cases
A6: - FunctionList: The list of Classes and Functions in the document. + To control that the number of Unit TC meets customer's requirement or the norm, user should fill value for 'Normal number of Test cases/KLOC'.
A7: + Click on Function link to open the related Test cases of the function. Note: You should create new Function sheet before creating the link
A8: - Test Report: provive the overview results of Functions Unit test: Test coverage, Test successful coverage (Summary, for normal/abnormal/boundary cases)
A9: Note: Should check the formula of "Sub Total" if you add more functions
A11: 2. Content in Test function sheet
A12: 2.1 Combination of test cases.
A13: - To verify that number of Unit TC meets customer's requirement or not. User has to fill number LOC of tested function and fill value of 'Normal number test cases/KLOC' item in FunctionList sheet, which is required by customer or normal value. The number of lacked TC is shown in 'Lack of test cases' item.
A14: - If the number of Unit TC does not meet the requirement, creator should explain the reasons.
A15: - If the number of 'Normal number test cases/KLOC' item in FunctionList sheet is not recorded, the number in 'Lack of test cases' is not calculated.
... A46: - Test requirement: Brief description about requirements which are tested in this function, it is not mandatory.

Sheet Cover
B2: UNIT TEST DOCUMENT
A4: Project Name | B4: VinaTech Smart Manufacturing's order status management system | E4: Creator | F4: SANGNV
A5: Project Code | B5: VTOMS | E5: Issue Date | F5: 46128
A6: Document Code | B6: VTOMS. Unit Test | E6: Version | F6: 1.3
A9: Record of change
A10: Effective Date | B10: Version | C10: Change Item | D10: *A,D,M | E10: Change description | F10: Reference
A11: 46128 | B11: 1.1 | C11: Update | D11: A | E11: Add Unit Test for Create Delivery | F11: VL01N, VL02N – Delivery & PGI
A12: 46129 | B12: 1.2 | C12: Update | D12: A | E12: Add Unit Test for Create Sales Order | F12: VA01 – Create Sales Order
A13: 46130 | B13: 1.3 | C13: Update | D13: A | E13: Add Unit Test for Create Return Order | F13: VA01 – Create Sales Order

Sheet Statistics
A2: UNIT TEST REPORT
A4: Project Name | B4: =Cover!B4 -> VinaTech Smart Manufacturing's order status management system | D4: Creator | F4: SANGNV
A5: Project Code | B5: =Cover!B5 -> VTOMS | D5: Reviewer/Approver | F5: MANHNC
A6: Document Code | B6: =Cover!B6 -> VTOMS. Unit Test | D6: Issue Date | F6: 46129
A7: Notes
A11: No | B11: Function code | C11: Passed | D11: Failed | E11: Untested | F11: Total Test Cases
A12: 1 | B12: Create Sales Order (VA01) | C12: ='Create Sales Order (VA01)'!A5 -> 9 | D12: ='Create Sales Order (VA01)'!D5 -> 0 | E12: ='Create Sales Order (VA01)'!F5 -> 0 | F12: =E12+D12+C12 -> 9
A13: 2 | B13: Create Delivery | C13: ='Create Delivery'!A5 -> 7 | D13: ='Create Delivery'!D5 -> 0 | E13: ='Create Delivery'!F5 -> 0 | F13: =E13+D13+C13 -> 7
A14: 3 | B14: Create Return Order (VA01) | C14: ='Create Return Order (VA01)'!A5 -> 5 | D14: ='Create Return Order (VA01)'!D5 -> 1 | E14: ='Create Return Order (VA01)'!F5 -> 0 | F14: =E14+D14+C14 -> 6
B15: Sub total | C15: =SUM(C12:C14) -> 21 | D15: =SUM(D12:D14) -> 1 | E15: =SUM(E12:E13) -> 0 | F15: =F12+F13+F14 -> 22
B17: Test coverage | D17: =(C15+D15)*100/(F15) -> 100 | E17: %
B18: Test successful coverage | D18: =C15*100/(F15) -> 95.454545 | E18: %

Sheet MethodList
C2: Method List
A4: Project Name | C4: =Cover!B4 -> VinaTech Smart Manufacturing's order status management system
A5: Project Code | C5: GIVAT
A6: Normal number of Test cases/KLOC
A7: Test Environment Setup Description
A10: No | B10: Module Name | C10: Method Name | D10: Sheet Name | E10: Description | F10: Pre-Condition
A11: 1 | B11: Sales&Distribution | C11: Create Sales Order (VA01) | D11: Create Sales Order (VA01)
C12: Create Delivery | D12: Create Delivery
C13: Create Return Order (VA01) | D13: Create Return Order (VA01)

Sheet Create Sales Order (VA01)
A1: Code Module | D1: Create Sales Order (VA01) | F1: Method | G1: Create Sales Order (VA01)
A2: Created By | D2: SANGNV | F2: Executed By | G2: SANGNV
A3: Test requirement | D3: Unit test for Create Sales Order (VA01) – covers positive, negative, and boundary cases in the SD O2C process.
A4: Passed | D4: Failed | F4: Untested | G4: Total Test Cases
A5: =COUNTIF(J8:J916, "Passed") -> 9 | D5: 0 | F5: 0 | G5: =F5+D5+A5 -> 9
A7: Process | B7: ID | C7: Test Data | F7: Step | G7: Expected Result | H7: Actual Result | I7: Tester | J7: Pass/Fail
A8: Create Sales Order | B8: UT-SO-01 | C8: Order Header | D8: Order Type | E8: ZVT1 (VTC Standard Order) | F8: "1. T-Code: VA01 2. Enter Order Type: ZVT1 3. Sales Area: VT01 / VW / E2 4. Sold-to Party: 100121 Ship-to: 100121 Cust. Ref.: 100121 5. Sales tab: Pyt Terms: ZVT1 Incoterms:ZEV 6. Line Item 1: Material=650, Qty=1 PAL, Plant=VTHN 7. Item 650 → Conditions tab: verify PRVT, ZDIS, MWST 8. Save" | G8: Standard Order created. Msg: 'VTC Standard Order XXXXXXXXXX saved'. Item 650 Conditions: - PRVT: 50,000,000 VND/PAL - ZDIS: 5% = -2,500,000 VND - Net: 47,500,000 VND - MWST: 4,750,000 VND (10%) Plant VTHN auto-determined. Pyt Terms Z001 applied. Delivery date confirmed. | J8: Passed
D9: Sales Org. | E9: VT01 (VinaTech Smart Manuf.)
D10: Distr. Channel | E10: VW (VinaTech Wholesale)
D11: Division | E11: E2 (Electronics)
C12: Sales | D12: Pyt Terms | E12: ZVT1
D13: Incoterms | E13: ZEV
C14: Customer | D14: Sold-to Party | E14: 100121
D15: Ship-to Party | E15: 100121
D16: Cust. Reference | E16: 100121
C17: Line Item 1 | D17: Material | E17: 650 (bang mach den led)
D18: Order Qty | E18: 1
D19: Unit | E19: PAL
D20: Plant | E20: VTHN
D21: Storage Location | E21: FG01
C22: Conditions (Mat. 650) | D22: PRVT – VTC Price | E22: 50,000,000 VND / 1 PAL
D23: ZDIS – VinaTech Discount | E23: 5% → -2,500,000 VND
D24: MWST – Output Tax | E24: 10% → 4,750,000 VND
D25: Net Value | E25: 47,500,000 VND
D26: Tax | E26: 4,750,000 VND
B27: UT-SO-02 | C27: Order Header | D27: Order Type | E27: ZVT1 | F27: 1. T-Code: VA01 2. Order Type: ZVT1 3. Sales Area: VT01/VW/E2 4. Enter Sold-to Party: 999999 5. Press Enter | G27: [Negative] Error: 'No customer master record exists for sold-to party 999999'. Order cannot proceed. | I27: SANGNV | J27: Passed
D28: Sales Org. | E28: VT01
D29: Distr. Channel | E29: VW
D30: Division | E30: E2
C31: Customer | D31: Sold-to Party | E31: 999999
B32: UT-SO-03 | C32: Order Header | D32: Order Type | E32: ZVT1 | F32: 1. T-Code: VA01 2. Order Type: ZVT1, Sales Area: VT01/VW/E2 3. Sold-to Party: 100121 Ship-to: 100121 Cust. Ref.: 100121 4. Sales tab: Pyt Terms: ZVT1 5. Enter Material: ZZZ999 6. Press Enter | G32: [Negative] Error: 'Material ZZZ999 is not defined for sales org.VT01, distr.chan.VW, language EN'. Line item not accepted. | I32: SANGNV | J32: Passed
D33: Sales Org. | E33: VT01
D34: Distr. Channel | E34: VW
D35: Division | E35: E2
C36: Sales | D36: Pyt Terms | E36: ZVT1
C37: Customer | D37: Sold-to Party | E37: 100121
D38: Ship-to Party | E38: 100121
D39: Cust. Reference | E39: 100121
C40: Line Item | D40: Material | E40: ZZZ999 (Invalid)
D41: Order Qty | E41: 1
...

Sheet Create Delivery
A1: Code Module | D1: Create Sales Order (VA01) | F1: Method | G1: Create Sales Order (VA01)
A2: Created By | D2: SANGNV | F2: Executed By | G2: SANGNV
A3: Test requirement | D3: Unit test for Create Sales Order (VA01) – covers positive, negative, and boundary cases in the SD O2C process.
A4: Passed | D4: Failed | F4: Untested | G4: Total Test Cases
A5: =COUNTIF(J8:J981, "Passed") -> 7 | D5: 0 | F5: 0 | G5: =F5+D5+A5 -> 7
A7: Process | B7: ID | C7: Test Data | F7: Step | G7: Expected Result | H7: Actual Result | I7: Tester | J7: Pass/Fail
A8: Create Outbound Delivery | B8: UT-DL-01 | C8: Shipping | D8: Shipping Point | E8: SP02 (VTHN In-house) | F8: 1. T-Code: VL01N 2. Shipping Point: SP02 3. Selection Date: today 4. Enter Sales Order number 5. Check item data 6. Save | G8: Outbound Delivery created. Message: 'Outbound Delivery XXXXXXXX saved'. SP02 on header. FG01 on item. Linked to SO in document flow. | I8: SANGNV | J8: Passed
D9: Selection Date | E9: Today (16/04/2026)
C10: Reference | D10: Sales Order No. | E10: [from UT-SO-01]
C11: Delivery Item | D11: Material | E11: 650
D12: Delivery Qty | E12: 1 PAL
D13: Plant | E13: VTHN
D14: Storage Location | E14: FG01
B15: UT-DL-02 | C15: Block | D15: Delivery Block | E15: 01 (Credit Limit) | F15: 1. VA02 → set Delivery Block=01 on SO 2. T-Code: VL01N → SP02 3. Enter blocked SO number 4. Execute | G15: [Negative] No delivery created. Error/Warning: 'Sales order is blocked for delivery: Bottleneck material'. Cannot proceed. | I15: SANGNV | J15: Passed
D16: Set via | E16: VA02 → Header → Shipping
C17: Shipping | D17: Shipping Point | E17: SP02
C18: Reference | D18: Sales Order | E18: [blocked SO]
B19: UT-DL-03 | C19: Shipping | D19: Shipping Point | E19: ZZZZ (Invalid) | F19: 1. T-Code: VL01N 2. Shipping Point: ZZZZ 3. Enter any date and SO 4. Execute | G19: [Negative] Error: 'Shipping Point ZZZZ does not exist'. Cannot proceed. | I19: SANGNV | J19: Passed
C20: Reference | D20: Sales Order | E20: [valid SO]
B21: UT-DL-04 | C21: Shipping | D21: Shipping Point | E21: SP02 | F21: 1. Create SO with shipping condition triggering SP02 2. T-Code: VL01N → SP02 3. Check delivery header | G21: Shipping Point = SP02 on delivery. Auto-determined per shipping condition. | I21: SANGNV | J21: Passed
D22: Shipping Condition | E22: 02 (Express)
C23: Reference | D23: Sales Order | E23: [SO with Express condition]
C24: Delivery | D24: Shipping Point Result | E24: SP02
B25: UT-DL-05 | C25: Delivery | D25: Delivery No. | E25: [from UT-DL-01] | F25: 1. T-Code: VL01N → reference SO from UT-SO-01 2. Change delivery qty to 6 PAL (partial) 3. Save | G25: Partial delivery for 6 PAL created. SO still has 4 PAL open. System proposes 4 PAL on next delivery run. | I25: SANGNV | J25: Passed
C26: Split | D26: Original Qty | E26: 10 PAL
D27: 1st Delivery Qty | E27: 6 PAL (partial)
D28: Remaining Qty | E28: 4 PAL (open on SO)
A29: Picking Confirmation | B29: UT-DL-06 | C29: Delivery | D29: Delivery No. | E29: [from UT-DL-01] | F29: 1. T-Code: VL02N → enter delivery number 2. Go to Picking tab 3. SLoc=FG01, Picked Qty=1 PAL 4. Save | G29: Picking status = 'Fully Picked'. Storage location FG01 confirmed. Delivery ready for PGI. | I29: SANGNV | J29: Passed
C30: Picking | D30: Storage Location | E30: FG01
D31: Picked Qty | E31: 1 PAL
D32: Unit | E32: PAL
C33: Status | D33: Picking Status | E33: Fully Picked (C)
B34: UT-DL-07 | C34: Delivery | D34: Delivery No. | E34: [delivery] | F34: 1. T-Code: VL02N → open delivery 2. Picking tab: leave Picked Qty=0 3. Click 'Post Goods Issue' | G34: [Negative] Error: 'Picking not completed'. PGI blocked. Must complete picking first. | I34: SANGNV | J34: Passed
C35: Picking | D35: Picked Qty | E35: 0 (not done)
C36: Action | D36: Post Goods Issue | E36: Attempted
D37: Items per HU | E37: 1 PAL per HU

Sheet Create Return Order (VA01)
A1: Code Module | D1: Create Sales Order (VA01) | F1: Method | G1: Create Sales Order (VA01)
A2: Created By | D2: SANGNV | F2: Executed By | G2: SANGNV
A3: Test requirement | D3: Unit test for Create Sales Order (VA01) – covers positive, negative, and boundary cases in the SD O2C process.
A4: Passed | D4: Failed | F4: Untested | G4: Total Test Cases
A5: =COUNTIF(J8:J911, "Passed") -> 5 | D5: =COUNTIF(J8:J911, "Failed") -> 1 | F5: 0 | G5: =F5+D5+A5 -> 6
A7: Process | B7: ID | C7: Test Data | F7: Step | G7: Expected Result | H7: Actual Result | I7: Tester | J7: Pass/Fail
A8: Create Return Order | B8: UT-RO-01 | C8: Order Header | D8: Order Type | E8: ZVT2 (VTC Return Order) | F8: 1. T-Code: VA01 2. Enter Order Type: ZVT2 3. Sales Area: VT01/VW/E2 4. Sold-to Party: 100121 5. Enter reference SO number from UT-SO-01 6. Enter Item: Material 650, Qty 1, Unit PAL 7. Enter Reason for Return 8. Save | G8: Return Order created. Msg: 'VTC Return Order XXXXX has been saved'. Order Type = ZVT2. Reference to original SO visible. | I8: SANGNV | J8: Passed
D9: Sales Org. | E9: VT01 (VinaTech Smart Manuf.)
D10: Distr. Channel | E10: VW (VinaTech Wholesale)
D11: Division | E11: E2 (Electronics)
C12: Sales | D12: Pyt Terms | E12: ZVT1
D13: Incoterms | E13: ZEV
C14: Customer | D14: Sold-to Party | E14: 100121
D15: Ship-to Party | E15: 100121
D16: Cust. Reference | E16: 100121
C17: Reference | D17: Original SO No. | E17: [from UT-SO-01]
C18: Line Item 1 | D18: Material | E18: 650 (bang mach den led)
D19: Return Qty | E19: 1
D20: Unit | E20: PAL
D21: Plant | E21: VTHN
D22: Reason for Return | E22: Defective product
C23: Conditions (Mat. 650) | D23: PRVT – VTC Price | E23: 50,000,000 VND / 1 PAL (credit)
D24: ZDIS – VinaTech Discount | E24: 5% → -2,500,000 VND
D25: MWST – Output Tax | E25: 10% → 4,750,000 VND
D26: Net Value | E26: 47,500,000 VND (credit)
D27: Tax | E27: 4,750,000 VND
B28: UT-RO-02 | C28: Order Header | D28: Order Type | E28: ZVT2 | F28: 1. T-Code: VA01 2. Order Type: ZVT2 3. Sales Area: VT01/VW/E2 4. Sold-to Party: 999999 (invalid) 5. Enter | G28: [Negative] Error: 'No customer master record exists for sold-to party 999999'. Return Order not created. | I28: SANGNV | J28: Passed
D29: Sales Org. | E29: VT01
D30: Distr. Channel | E30: VW
D31: Division | E31: E2
C32: Customer | D32: Sold-to Party | E32: 999999 (Invalid)
B33: UT-RO-03 | C33: Order Header | D33: Order Type | E33: ZVT2 | F33: 1. T-Code: VA01 2. Order Type: ZVT2, Sales Area: VT01/VW/E2 3. Sold-to Party: 100121 4. Material: ZZZ999 (invalid) 5. Save | G33: [Negative] Error: 'Material ZZZ999 is not defined for sales org VT01'. Return Order not created. | I33: SANGNV | J33: Passed
D34: Sales Org. | E34: VT01
D35: Distr. Channel | E35: VW
D36: Division | E36: E2
C37: Customer | D37: Sold-to Party | E37: 100121
C38: Line Item | D38: Material | E38: ZZZ999 (Invalid)
D39: Return Qty | E39: 1
D40: Unit | E40: PAL
B41: UT-RO-04 | C41: Order Header | D41: Order Type | E41: ZVT2 | F41: 1. T-Code: VA01 → ZVT2, VT01/VW/E2 2. Sold-to Party: 100121 3. Reference original SO (Qty=1 PAL) 4. Enter Return Qty: 10 PAL (exceeds original) 5. Save | G41: [Negative] Warning/Error: Return quantity exceeds original order quantity. System should warn or block. | I41: SANGNV | J41: Failed
...
