Workbook
Name A: #REF!
Name A: #REF!
Name aaa: {"'Sheet1'!$A$1:$I$153"}
Name aaaa: {"'帳票一覧'!$A$1:$E$86"}
Name aaaa: {"'帳票一覧'!$A$1:$E$86"}
Name HTML_CodePage: 932
Name HTML_Control: {"'帳票一覧'!$A$1:$E$86"}
Name HTML_Control: {"'帳票一覧'!$A$1:$E$86"}
Name HTML_Control2: {"'Sheet1'!$A$1:$I$153"}
Name HTML_Description: ""
Name HTML_Email: ""
Name HTML_Header: "帳票一覧"
Name HTML_LastUpdate: "99/01/14"
Name HTML_LineAfter: FALSE
Name HTML_LineBefore: FALSE
Name HTML_Name: "北澤真弓"
Name HTML_OBDlg2: TRUE
Name HTML_OBDlg4: TRUE
Name HTML_OS: 0
Name HTML_PathFile: "C:\USR\LISTVIEW帳票\帳票一覧.htm"
Name HTML_Title: "総括表"
Name SAPBEXrevision: 1
Name SAPBEXsysID: "HA3"
Name SAPBEXwbID: "3UO1SYYEF96FKJ4L64UVYYKHM"
Name SSSS: {"'Sheet1'!$A$1:$I$153"}
Name あ: {"'Sheet1'!$A$1:$I$153"}

Sheet 01.Cover
A1: Docs_ID | D1: =Y12 -> TS_UPLOAD_SO | K1: Sheet name | O1: =MID(CELL("filename",A1),FIND("]",CELL("filename",A1))+1,255) -> 01.Cover | V1: Document | Z1: ='01.Cover'!B9 -> Technical Specification
B9: Technical Specification
P12: Document_ID | Q12: TS_ZCL_CUST_RANK_YTD_CDS | Y12: TS_UPLOAD_SO
P13: Version no | Q13: 1.0 | Y13: 1.0 | AK13: =TEXT(AH13,)
P14: Last updated date | Q14: 2026-04-29 | Y14: 29/04/2026
M19: Title | S19: Name | AB19: Code | AI19: Date
M20: Creator | S20: DatNV | AB20: HE171534 | AI20: 46360
M21: Reviewer
M22: Approver

Sheet 02.Revision_History
A1: Docs_ID | D1: ='01.Cover'!Y12 -> TS_UPLOAD_SO | K1: Sheet name | O1: =MID(CELL("filename",A1),FIND("]",CELL("filename",A1))+1,255) -> 02.Revision_History | V1: Document | Z1: ='01.Cover'!B9 -> Technical Specification
B5: No | D5: Date | J5: Name | S5: Code | V5: Changing
B7: 1 | D7: 2026-04-29 | J7: Initial draft generated from user-provided code

Sheet TS.Content
A1: Docs_ID | D1: ='01.Cover'!Y12 -> TS_UPLOAD_SO | K1: Sheet name | O1: =MID(CELL("filename",A1),FIND("]",CELL("filename",A1))+1,255) -> TS.Content | V1: Document | Z1: ='01.Cover'!B9 -> Technical Specification
O3: TS_UPLOAD_SO
B5: # | F5: Content | AA5: Note
B6: 1 | F6: Overview | AA6: Section overview
B7: 2 | F7: Technical Details | AA7: Architecture, tables, interfaces
B8: 3 | F8: Screen Layout | AA8: Background execution / N.A.
B9: 4 | F9: Processing Logic | AA9: Detailed logic and pseudo flow

Sheet TS.Overview
A1: Docs_ID | D1: ='01.Cover'!Y12 -> TS_UPLOAD_SO | K1: Sheet name | O1: =MID(CELL("filename",A1),FIND("]",CELL("filename",A1))+1,255) -> TS.Overview | V1: Document | Z1: ='01.Cover'!B9 -> Technical Specification
O3: TS_UPLOAD_SO
A4: I. Overview
D7: OBJECT OVERVIEW
D8: Object Name: ZCL_CUST_RANK_YTD_CDS
D10: Technical Name | T10: ZCL_CUST_RANK_YTD_CDS
D11: Description | T11: Mass upload Sales Orders from Excel into SAP staging tables, validate against master data & pricing, review/edit on OO ALV, and post via BAPI_SALESORDER_CREATEFROMDAT2
D12: Development Package | T12: ZPK_SAP490_G9_SP26
D13: Message Class | T13: N/A (inline messages)
D14: Program Type | T14: Executable Report (Type 1) + Screen 100 (OO ALV) + Background Jobs
D15: Development Type (F/R/I/C/E) | T15: C (Custom Development)
D16: Processes / SAP Module | T16: SD / Sales Order Creation / Mass Upload
D17: SAP System / Release | T17: ABAP Application Server
D18: Priority (High/Medium/Low) | T18: High
D19: Complexity (Simple/Medium/Complex/Very complex) | T19: Complex

Sheet TS.Technical Details
A1: Docs_ID | D1: ='01.Cover'!Y12 -> TS_UPLOAD_SO | K1: Sheet name | O1: =MID(CELL("filename",A1),FIND("]",CELL("filename",A1))+1,255) -> TS.Technical Details | V1: Document | Z1: ='01.Cover'!B9 -> Technical Specification
O3: TS_UPLOAD_SO
A5: 2 Technical Details
C6: 2.1 Program Structure
C8: Two standalone programs + two background jobs:
C10: Program 1: ZPG_UPLOAD_SO (Single file, no includes)
C11: - Selection Screen 1000: File path input + Download Template pushbutton
C12: - Reads Excel via ALSM_EXCEL_TO_INTERNAL_TABLE (row 2+, cols 1-15)
C13: - Generates UUID batch ID via CL_SYSTEM_UUID=>CREATE_UUID_X16_STATIC
C14: - Maps Excel rows → Z tables (groups by header key, items numbered by 10)
C15: - INSERT into ZTB_SD_SO_HEADER + ZTB_SD_SO_ITEM (status = N)
C16: - Auto-submits background job Z_SO_VALIDATE_JOB (JOB_OPEN → SUBMIT → JOB_CLOSE)
C18: Program 2: ZPG_SO_ALV_EDIT (Main + 5 Includes)
C19: - ZPG_SO_ALV_EDIT_TOP: Types (TY_ALV with CELLTAB), Constants (GC_STATUS), Global data (GO_GRID, GO_CONTAINER)
C20: - ZPG_SO_ALV_EDIT_CLS: Local class LCL_EVENT_HANDLER
... C59: 2.3 Data Flow
C61: Step | O61: Details
C62: 1. Read Excel | O62: ALSM_EXCEL_TO_INTERNAL_TABLE reads from row 2, columns 1-15. Maps CASE col → TY_EXCEL_LINE fields.
C63: 2. Generate UUID | O63: CL_SYSTEM_UUID creates unique batch ID for all records in this upload.
C64: 3. Group by Header | O64: Concatenate AUART+VKORG+VTWEG+SPART+KUNNR+KUNWE+BSTKD+ZTERM+INCO1+INCO2 as grouping key. Same key = 1 SO header. VDATU excluded (moved to schedule line). Items numbered 10, 20, 30...
C65: 4. Convert & Insert | O65: ALPHA_INPUT for customers, MATN1_INPUT for materials. MODIFY Z tables. COMMIT WORK AND WAIT.
C66: 5. Validate (BG Job) | O66: Level 1: Mandatory check. Level 2: Master data (KNA1, KNVV, MARA, MVKE, T001W, TVKO, T052, customer block). Level 3: BAPI simulate (TESTRUN=X) → read ORDER_CONDITIONS_IN by COND_CLASS.
C67: 6. ALV Review | O67: SELECT Z tables JOIN → GT_ALV. OO ALV editable. Real-time validation on cell change. Save → UPDATE Z tables (reset status N). Validate → save + submit validate job.
C68: 7. Post (BG Job) | O68: BAPI_SALESORDER_CREATEFROMDAT2 (no TESTRUN). COMMIT on success (status P + VBELN). ROLLBACK on failure (status X).
C69: 8. Lock Posted | O69: Status P records: CELLTAB set to mc_style_disabled. Validate/Save skip status P. Prevents duplicate SO creation.
C71: 2.4 Error Handling
C73: Type | L73: Details
C74: Empty Excel | L74: ALSM returns empty → MESSAGE "No data in Excel!" TYPE E. Processing stops.
C75: Mandatory Missing | L75: Validate job checks AUART, VKORG, VTWEG, SPART, KUNNR. First empty field → status E + specific message.
C76: Master Data Not Found | L76: SELECT SINGLE from KNA1/MARA/MVKE/T001W/TVKO/T052. sy-subrc <> 0 → status E + "{field} does not exist".
C77: Customer Blocked | L77: KNVV-AUFSD not initial → status E + "Customer blocked for sales".
C78: BAPI Simulation Error | L78: RETURN table type E/A/X → concatenate messages → status E. No pricing stored.
C79: BAPI Post Error | L79: RETURN errors → BAPI_TRANSACTION_ROLLBACK → status X + error message. Items also set to X.
C80: Duplicate Upload | L80: Check BSTKD + KUNNR + MATNR combination in Z table before insert. Popup warning if found.
C81: ALV Real-time Error | L81: ADD_PROTOCOL_ENTRY → popup error message immediately when user edits cell with invalid value.
C82: Job Creation Failure | L82: JOB_OPEN sy-subrc <> 0 → MESSAGE "Error creating background job!" TYPE E.
C84: 2.5 Security
C85: Aspect | O85: Details
C86: Authorization Object | O86: V_VBAK_VKO — checks VKORG + VTWEG + SPART + ACTVT (01=Create, 02=Change, 03=Display)
C87: Transaction Code | O87: ZPG_SO_ALV_EDIT assigned with Auth Object V_VBAK_VKO in SE93
...

Sheet TS.Screen Layout
B2: Screen Layout | AQ2: Created by: | AV2: DatNV | AY2: Created date: | BD2: 46122
B3: Function ID | F3: =[1]Cover!N12 -> ZPG_UPLOAD_SO / ZPG_SO_ALV_EDIT | P3: Function Name | U3: =[1]Cover!N13 -> Upload Sales Order from Excel & ALV Review | AQ3: Modified by: | AV3: DatNV | AY3: Modified date: | BD3: 46133
B5: Screen 1000 (Selection Screen) — ZPG_UPLOAD_SO
B30: Screen 1000 (Selection Screen) — ZPG_SO_ALV_EDIT
B48: Screen 100 (OO ALV) — ZPG_SO_ALV_EDIT
B64: Status Icons:
B66: 🟢 Green (V) = Validated — pricing determined, ready to post
B67: 🔴 Red (E) = Error — validation failed, see Message column
B68: ✅ Check (P) = Posted — SO created successfully, locked
B69: ⚠️ Warn (X) = Post Error — BAPI failed, see Message column

Sheet TS.Processing Logic
A1: Docs_ID | D1: ='01.Cover'!Y12 -> TS_UPLOAD_SO | K1: Sheet name | O1: =MID(CELL("filename",A1),FIND("]",CELL("filename",A1))+1,255) -> TS.Processing Logic | V1: Document | Z1: ='01.Cover'!B9 -> Technical Specification
O3: TS_UPLOAD_SO
A5: 4 PROCESSING LOGIC
C6: 4.1 Upload Excel Processing (ZPG_UPLOAD_SO)
C7: Purpose
C8: Read Excel file, map to staging tables, auto-submit validation background job.
C9: Logic
C10: 1. ALSM_EXCEL_TO_INTERNAL_TABLE(filename=P_FILE, i_begin_row=2, i_begin_col=1, i_end_col=15, i_end_row=9999).
C11: 2. Loop ALSMEX_TABLINE: track row changes → APPEND TY_EXCEL_LINE on row break. CASE COL for field mapping.
C12: 3. CL_SYSTEM_UUID=>CREATE_UUID_X16_STATIC → LV_UUID. Fallback: concatenate SY-UNAME+DATUM+UZEIT.
C13: 4. Group by header key (AUART+VKORG+VTWEG+SPART+KUNNR+KUNWE+BSTKD+ZTERM+INCO1+INCO2). VDATU excluded from key.
C14: 5. CONVERSION_EXIT_ALPHA_INPUT for KUNNR/KUNWE. CONVERSION_EXIT_MATN1_INPUT for MATNR.
C15: 6. Item numbering: LV_ITEM_NO = LV_ITEM_NO + 10 per line within same header group.
C16: 7. Default: WAERK = "VND", ZSTATUS = GC_STATUS-NEW, ERNAM/ERDAT/ERTIM = SY-UNAME/DATUM/UZEIT.
C17: 8. MODIFY ZTB_SD_SO_HEADER FROM TABLE. MODIFY ZTB_SD_SO_ITEM FROM TABLE. COMMIT WORK AND WAIT.
... C20: 4.2 Validation Processing (Z_SO_VALIDATE_JOB)
D21: Purpose
D22: Validate staging data against master data and simulate BAPI to determine pricing.
D23: Logic
D24: 1. SELECT * FROM ZTB_SD_SO_HEADER/ITEM INTO CORRESPONDING FIELDS OF TABLE WHERE ZREQ_ID = P_REQID AND ZSTATUS = N.
D25: 2. Level 1 — Mandatory: Check AUART, VKORG, VTWEG, SPART, KUNNR not initial. First failure → status E + message.
D26: 3. Level 2 — Master Data:
D27: SELECT SINGLE FROM KNA1 WHERE KUNNR = header-KUNNR. Not found → E "Customer not found".
D28: SELECT SINGLE AUFSD FROM KNVV WHERE KUNNR+VKORG+VTWEG+SPART. Not found → E "Not maintained for Sales Area". AUFSD not initial → E "Blocked".
D29: SELECT SINGLE FROM KNA1 WHERE KUNNR = header-KUNWE (if not initial). Not found → E.
D30: SELECT SINGLE FROM TVKO WHERE VKORG. Not found → E.
D31: SELECT SINGLE FROM T052 WHERE ZTERM (if not initial). Not found → E.
D32: Per item: SELECT SINGLE FROM MARA WHERE MATNR. Not found → E.
... D45: 5. MODIFY ZTB_SD_SO_HEADER/ITEM FROM TABLE. COMMIT WORK AND WAIT.
C47: 4.3 Post Processing (Z_SO_POST_JOB)
D48: Purpose
D49: Create real Sales Orders from validated staging data.
D50: Logic
D51: 1. SELECT * FROM Z tables WHERE ZSTATUS = V.
D52: 2. Per header: build same BAPI structures as validate (without TESTRUN).
D53: 3. CALL FUNCTION BAPI_SALESORDER_CREATEFROMDAT2.
D54: 4. Check RETURN for errors:
D55: Errors found → BAPI_TRANSACTION_ROLLBACK → status X + concatenated error messages.
D56: No errors → BAPI_TRANSACTION_COMMIT(WAIT=X) → status P + VBELN from IMPORTING SALESDOCUMENT.
D57: 5. Update all items of same ZREQ_ID to matching status (P or X).
...
